<?xml version="1.0"?>
<robot xmlns:xacro="http://www.ros.org/wiki/xacro" name="firefighter">

  <xacro:property name="width" value=".2" />


  <link name="base">
    <visual>
      <geometry>
        <mesh filename="package://mycobot_description/urdf/new_320_pi/base.dae"/>
      </geometry>
      <origin xyz = "0 0 0 " rpy = " 0 0 3.1415926"/>
    </visual>
    <collision>
      <origin xyz = "0 0 0.05 " rpy = " 0 0 3.1415926"/>
      <geometry>
        <cylinder length="0.102" radius="0.0725"/>
      </geometry>
    </collision>
  </link>

  <link name="link1">
    <visual>
      <geometry>
        <mesh filename="package://mycobot_description/urdf/new_320_pi/link1.dae"/>
      </geometry>
      <origin xyz = "0.115 -0.172 -0.086 " rpy = " 0 0 3.1415926"/>
    </visual>
    <collision>
      <origin xyz = "0 0 -0.02 " rpy = " 0 0 3.14159"/>
      <geometry>
        <cylinder length="0.106" radius="0.043"/>
      </geometry>
    </collision>
  </link>


  <link name="link2">
    <visual>
      <geometry>
        <mesh filename="package://mycobot_description/urdf/new_320_pi/link2.dae"/>
      </geometry>
     <origin xyz = "-0.075 -0.115 -0.022 " rpy = " 1.5708 0 1.5708"/>
    </visual>
    <collision>
      <origin xyz = "0.07 0 0.095 " rpy = " 0 1.5708 0"/>
      <geometry>
        <cylinder length="0.18" radius="0.036"/>
      </geometry>
    </collision>
  </link>


  <link name="link3">
    <visual>
      <geometry>
        <mesh filename="package://mycobot_description/urdf/new_320_pi/link3.dae"/>
      </geometry>
     <origin xyz = "-0.22 -0.115 0.142 " rpy = " 1.5708 0 1.5708"/>
    </visual>
    <collision>
      <origin xyz = "0.044 0 0 " rpy = " 1.5708 0 1.5708"/>
      <geometry>
        <cylinder length="0.14" radius="0.0305"/>
      </geometry>
    </collision>
  </link>



  <link name="link4">
    <visual>
      <geometry>
        <mesh filename="package://mycobot_description/urdf/new_320_pi/link4.dae"/>
      </geometry>
      <origin xyz = "-0.115 0.338 -0.1435" rpy = " 1.5708 0 0"/>
    </visual>
    <collision>
      <origin xyz = "0.0 -0.014 0 " rpy = " 1.5708 0 0"/>
      <geometry>
        <cylinder length="0.083" radius="0.029"/>
      </geometry>
    </collision>
  </link>


  <link name="link5">
    <visual>
      <geometry>
        <mesh filename="package://mycobot_description/urdf/new_320_pi/link5.dae"/>
      </geometry>
       <origin xyz = "-0.1149 -0.0322  -0.482 " rpy = " 0  0 0"/>
    </visual>
    <collision>
      <origin xyz = "0 -0.01 0 " rpy = " 0 0 0"/>
      <geometry>
        <cylinder length="0.0849" radius="0.029"/>
      </geometry>
    </collision>
  </link>

  <link name="link6">
    <visual>
      <geometry>
        <mesh filename="package://mycobot_description/urdf/new_320_pi/link6.dae"/>
      </geometry>
      <material name = "grey">
        <color rgba = "0.5 0.5 0.5 1"/>
      </material>
       <origin xyz = "-0.11478 0.433 -0.15 " rpy = " 1.5708 0 0"/>
    </visual>
    <collision>
      <origin xyz = "-0.431 0.0009 -0.16536 " rpy = " 1.5708 0 0"/>
      <geometry>
        <cylinder length="0.0225" radius="0.026"/>
      </geometry>
    </collision>
  </link>

  <joint name="joint2_to_joint1" type="revolute">
    <axis xyz="0 0 1"/>
    <limit effort = "1000.0" lower = "-2.96" upper = "2.96" velocity = "0"/>
    <parent link="base"/>
    <child link="link1"/>
    <origin xyz= "0 0 0.162" rpy = "0 0 0"/>
  </joint>


  <joint name="joint3_to_joint2" type="revolute">
    <axis xyz="0 0 1"/>
    <limit effort = "1000.0" lower = "-2.79" upper = "2.79" velocity = "0"/>
    <parent link="link1"/>
    <child link="link2"/>
    <origin xyz= "0 0  0" rpy = "0 -1.57080  1.57080"/>
  </joint>


  <joint name="joint4_to_joint3" type="revolute">
    <axis xyz=" 0 0 1"/>
    <limit effort = "1000.0" lower = "-2.79" upper = "2.79" velocity = "0"/>
    <parent link="link2"/>
    <child link="link3"/>
    <origin xyz= "0.13635 0 0   " rpy = "0 0 0"/>
  </joint>

  <joint name="joint5_to_joint4" type="revolute">
    <axis xyz=" 0 0 1"/>
    <limit effort = "1000.0" lower = "-2.79" upper = "2.79" velocity = "0"/>
    <parent link="link3"/>
    <child link="link4"/>
    <origin xyz= "0.1205 0  0.082" rpy = "0 0 1.57080"/>
  </joint>

  <joint name="joint6_to_joint5" type="revolute">
    <axis xyz="0 0 1"/>
    <limit effort = "1000.0" lower = "-2.96" upper = "2.96" velocity = "0"/>
    <parent link="link4"/>
    <child link="link5"/>
    <origin xyz= "0 -0.084 0" rpy = "1.57080 0 0"/>
  </joint>

  <joint name="joint6output_to_joint6" type="revolute">
    <axis xyz="0 0 1"/>
    <limit effort = "1000.0" lower = "-3.05" upper = "3.05" velocity = "0"/>
    <parent link="link5"/>
    <child link="link6"/>
    <origin xyz= "0 0.06635 0" rpy = "-1.57080 0 0 "/>
  </joint>

</robot>

