<?xml version="1.0" ?>
<robot xmlns:xacro="http://www.ros.org/wiki/xacro" name="firefighter">
    <xacro:property name="width" value=".2" />
    <link name="base">
        <visual>
            <geometry>
                <mesh filename="package://mycobot_description/urdf/mycobot_630/base.dae" />
            </geometry>
            <origin xyz="0 0 0 " rpy=" 1.5707 0 0" />
        </visual>
        <collision>
            <geometry>
                <mesh filename="package://mycobot_description/urdf/mycobot_630/base.dae" />
            </geometry>
            <origin xyz="0 0 0 " rpy=" 1.5707 0 0" />
        </collision>
        
<inertial>
            <mass value="1000" />
            <inertia ixx="0.03" iyy="0.03" izz="0.03" ixy="0.0" ixz="0.0" iyz="0.0" />
        </inertial>

    </link>
    <link name="link1">
        <visual>
            <geometry>
                <mesh filename="package://mycobot_description/urdf/mycobot_630/link1.dae" />
            </geometry>
            <origin xyz="0 0 -0.06 " rpy="0 0 3.1415926" />
        </visual>
        <collision>
            <geometry>
                <mesh filename="package://mycobot_description/urdf/mycobot_630/link1.dae" />
            </geometry>
            <origin xyz="0 0 -0.06 " rpy=" 0 0 3.1415926" />
        </collision>
        
<inertial>
            <mass value="100" />
            <inertia ixx="0.03" iyy="0.03" izz="0.03" ixy="0.0" ixz="0.0" iyz="0.0" />
        </inertial>

    </link>
    <link name="link2">
        <visual>
            <geometry>
                <mesh filename="package://mycobot_description/urdf/mycobot_630/link2.dae" />
            </geometry>
            <origin xyz="0 0 -0.0446 " rpy=" 1.5707 -1.5707 -1.5707" />
        </visual>
        <collision>
            <geometry>
                <mesh filename="package://mycobot_description/urdf/mycobot_630/link2.dae" />
            </geometry>
            <origin xyz="0 0 -0.0446 " rpy=" 1.5707 -1.5707 -1.5707" />
        </collision>
        
<inertial>
            <mass value="50" />
            <inertia ixx="0.03" iyy="0.03" izz="0.03" ixy="0.0" ixz="0.0" iyz="0.0" />
        </inertial>

    </link>
    <link name="link3">
        <visual>
            <geometry>
                <mesh filename="package://mycobot_description/urdf/mycobot_630/link3.dae" />
            </geometry>
            <origin xyz="0 0 -0.0444 " rpy=" 0 1.5707 0" />
        </visual>
        <collision>
            <geometry>
                <mesh filename="package://mycobot_description/urdf/mycobot_630/link3.dae" />
            </geometry>
            <origin xyz="0 0 -0.0444 " rpy="0 1.5707 0" />
        </collision>
        
<inertial>
            <mass value="10" />
            <inertia ixx="0.03" iyy="0.03" izz="0.03" ixy="0.0" ixz="0.0" iyz="0.0" />
        </inertial>

    </link>
    <link name="link4">
        <visual>
            <geometry>
                <mesh filename="package://mycobot_description/urdf/mycobot_630/link4.dae" />
            </geometry>
            <origin xyz="0 -0.002 0.041 " rpy=" -1.5707 0 -1.5707" />
        </visual>
        <collision>
            <geometry>
                <mesh filename="package://mycobot_description/urdf/mycobot_630/link4.dae" />
            </geometry>
            <origin xyz="0 -0.002 0.041 " rpy=" -1.5707 0 -1.5707" />
        </collision>
        
<inertial>
            <mass value="5" />
            <inertia ixx="0.03" iyy="0.03" izz="0.03" ixy="0.0" ixz="0.0" iyz="0.0" />
        </inertial>

    </link>
    <link name="link5">
        <visual>
            <geometry>
                <mesh filename="package://mycobot_description/urdf/mycobot_630/link5.dae" />
            </geometry>
            <origin xyz="-0.043 0 -0.08 " rpy=" 3.14159 1.5707 3.14159" />
        </visual>
        <collision>
            <geometry>
                <mesh filename="package://mycobot_description/urdf/mycobot_630/link5.dae" />
            </geometry>
            <origin xyz="-0.043 0 -0.08 " rpy=" 3.14159 1.5707 3.14159" />
        </collision>
        
<inertial>
            <mass value="1" />
            <inertia ixx="0.03" iyy="0.03" izz="0.03" ixy="0.0" ixz="0.0" iyz="0.0" />
        </inertial>

    </link>
    <link name="link6">
        <visual>
            <geometry>
                <mesh filename="package://mycobot_description/urdf/mycobot_630/link6.dae" />
            </geometry>
            <!-- <material name = "grey">
        <color rgba = "0.5 0.5 0.5 1"/>
      </material> -->
            <origin xyz="0.01 0 0" rpy=" 0 1.5707  0" />
        </visual>
        <collision>
            <geometry>
                <mesh filename="package://mycobot_description/urdf/mycobot_630/link6.dae" />
            </geometry>
            <!-- <material name = "grey">
        <color rgba = "0.5 0.5 0.5 1"/>
      </material> -->
            <origin xyz="0.01 0 0" rpy=" 0 1.5707  0" />
        </collision>
        
<inertial>
            <mass value="0.1" />
            <inertia ixx="0.03" iyy="0.03" izz="0.03" ixy="0.0" ixz="0.0" iyz="0.0" />
        </inertial>

    </link>
    <joint name="joint1_to_base" type="revolute">
        <axis xyz="0 0 1" />
        <limit effort="1000.0" lower="-3.14" upper="3.14159" velocity="1" />
        <parent link="base" />
        <child link="link1" />
        <origin xyz="0 0 0.22934" rpy="0 0 0" />
    </joint>
    <joint name="joint2_to_joint1" type="revolute">
        <axis xyz="0 0 -1" />
        <limit effort="1000.0" lower="-2.26" upper="2.26" velocity="1" />
        <parent link="link1" />
        <child link="link2" />
        <origin xyz="0 0  0" rpy="1.5707 0 0" />
    </joint>
    <joint name="joint3_to_joint2" type="revolute">
        <axis xyz=" 0 0 -1" />
        <limit effort="1000.0" lower="-2.61" upper="2.618" velocity="1" />
        <parent link="link2" />
        <child link="link3" />
        <origin xyz="0 0.27 0" rpy="0 0 0" />
    </joint>
    <joint name="joint4_to_joint3" type="revolute">
        <axis xyz=" 0 0 -1" />
        <limit effort="1000.0" lower="-3.17" upper="3.17" velocity="1" />
        <parent link="link3" />
        <child link="link4" />
        <origin xyz="0 0.267 -0.0745" rpy="0 0 0" />
    </joint>
    <joint name="joint5_to_joint4" type="revolute">
        <axis xyz="0 0 1" />
        <limit effort="1000.0" lower="-2.99" upper="2.99" velocity="1" />
        <parent link="link4" />
        <child link="link5" />
        <origin xyz="0 0 0.002" rpy="1.5707 -1.5707 0" />
    </joint>
    <joint name="joint6_to_joint5" type="revolute">
        <axis xyz="-1 0 0" />
        <limit effort="1000.0" lower="-3.03" upper="3.0368" velocity="1" />
        <parent link="link5" />
        <child link="link6" />
        <origin xyz="-0.054 0 -0.08" rpy="-1.5707 0 0 " />
    </joint>
    
<transmission name="trans_joint1_to_base">
        <type>transmission_interface/SimpleTransmission</type>
        <joint name="joint1_to_base">
            <hardwareInterface>hardware_interface/PositionJointInterface</hardwareInterface>
        </joint>
        <actuator name="joint1_to_base_motor">
            <hardwareInterface>hardware_interface/PositionJointInterface</hardwareInterface>
            <mechanicalReduction>1</mechanicalReduction>
        </actuator>
    </transmission>
    <transmission name="trans_joint2_to_joint1">
        <type>transmission_interface/SimpleTransmission</type>
        <joint name="joint2_to_joint1">
            <hardwareInterface>hardware_interface/PositionJointInterface</hardwareInterface>
        </joint>
        <actuator name="joint2_to_joint1_motor">
            <hardwareInterface>hardware_interface/PositionJointInterface</hardwareInterface>
            <mechanicalReduction>1</mechanicalReduction>
        </actuator>
    </transmission>
    <transmission name="trans_joint3_to_joint2">
        <type>transmission_interface/SimpleTransmission</type>
        <joint name="joint3_to_joint2">
            <hardwareInterface>hardware_interface/PositionJointInterface</hardwareInterface>
        </joint>
        <actuator name="joint3_to_joint2_motor">
            <hardwareInterface>hardware_interface/PositionJointInterface</hardwareInterface>
            <mechanicalReduction>1</mechanicalReduction>
        </actuator>
    </transmission>
    <transmission name="trans_joint4_to_joint3">
        <type>transmission_interface/SimpleTransmission</type>
        <joint name="joint4_to_joint3">
            <hardwareInterface>hardware_interface/PositionJointInterface</hardwareInterface>
        </joint>
        <actuator name="joint4_to_joint3_motor">
            <hardwareInterface>hardware_interface/PositionJointInterface</hardwareInterface>
            <mechanicalReduction>1</mechanicalReduction>
        </actuator>
    </transmission>
    <transmission name="trans_joint5_to_joint4">
        <type>transmission_interface/SimpleTransmission</type>
        <joint name="joint5_to_joint4">
            <hardwareInterface>hardware_interface/PositionJointInterface</hardwareInterface>
        </joint>
        <actuator name="joint5_to_joint4_motor">
            <hardwareInterface>hardware_interface/PositionJointInterface</hardwareInterface>
            <mechanicalReduction>1</mechanicalReduction>
        </actuator>
    </transmission>
    <transmission name="trans_joint6_to_joint5">
        <type>transmission_interface/SimpleTransmission</type>
        <joint name="joint6_to_joint5">
            <hardwareInterface>hardware_interface/PositionJointInterface</hardwareInterface>
        </joint>
        <actuator name="joint6_to_joint5_motor">
            <hardwareInterface>hardware_interface/PositionJointInterface</hardwareInterface>
            <mechanicalReduction>1</mechanicalReduction>
        </actuator>
    </transmission>
    <gazebo>
        <plugin name="gazebo_ros_control" filename="libgazebo_ros_control.so">
            <robotNamespace>/</robotNamespace>
        </plugin>
    </gazebo>
        <gazebo reference="base">
        <selfCollide>true</selfCollide>
    </gazebo>
    <gazebo reference="joint1">
        <selfCollide>true</selfCollide>
    </gazebo>
    <gazebo reference="joint2">
        <selfCollide>true</selfCollide>
    </gazebo>
    <gazebo reference="joint3">
        <selfCollide>true</selfCollide>
    </gazebo>
    <gazebo reference="joint4">
        <selfCollide>true</selfCollide>
    </gazebo>
    <gazebo reference="joint5">
        <selfCollide>true</selfCollide>
    </gazebo>
    <gazebo reference="joint6">
        <selfCollide>true</selfCollide>
    </gazebo>
</robot>