<?xml version="1.0"?>
<robot  xmlns:xacro="http://www.ros.org/wiki/xacro" name="firefighter1" >
	
<xacro:property name="width" value=".2" />

  <link name="gripper_base">
    <visual>
      <geometry>
       <!--- 0.0 0 -0.04 -->
       <mesh filename="package://mycobot_description/urdf/force_control_gripper/pro_gripper_base.dae"/>
      </geometry>
    <origin xyz = "-0.107 0.012 0.0 " rpy = " 1.5708  0 1.5708"/>
    </visual>
    <collision>
      <geometry>
       <!--- 0.0 0 -0.04 -->
       <mesh filename="package://mycobot_description/urdf/force_control_gripper/pro_gripper_base.dae"/>
      </geometry>
    <origin xyz = "-0.107 0.012 0.0 " rpy = " 1.5708  0 1.5708"/>
    </collision>
  </link>

  <link name="gripper_left1">
    <visual>
      <geometry>
       <!--- 0.0 0 -0.04 -->
       <mesh filename="package://mycobot_description/urdf/force_control_gripper/pro_gripper_left1.dae"/>
      </geometry>
    <origin xyz = "-0.047 -0.013 0.044 " rpy = " 1.5708 0 1.5708"/>
    </visual>
    <collision>
      <geometry>
       <mesh filename="package://mycobot_description/urdf/force_control_gripper/pro_gripper_left1.dae"/>
      </geometry>
        <origin xyz = "-0.047 -0.013 0.044 " rpy = " 1.5708 0 1.5708"/>
    </collision>
  </link>

  <link name="gripper_left2">
    <visual>
      <geometry>
       <mesh filename="package://mycobot_description/urdf/force_control_gripper/pro_gripper_left2.dae"/>
      </geometry>
    <origin xyz = "-0.0 0.03 0.004 " rpy = " 3.14159 0 1.5708"/>
    </visual>
    <collision>
      <geometry>
       <mesh filename="package://mycobot_description/urdf/force_control_gripper/pro_gripper_left2.dae"/>
      </geometry>
        <origin xyz = "-0.0 0.03 0.004 " rpy = " 3.14159 0 1.5708"/>
    </collision>
  </link>

  <link name="gripper_left3">
    <visual>
      <geometry>
       <mesh filename="package://mycobot_description/urdf/force_control_gripper/pro_gripper_left3.dae"/>
      </geometry>
    <origin xyz = "0 -0.03 0.012 " rpy = " 1.5708 3.14159 1.5708"/>

    </visual>
    <collision>
      <geometry>
       <mesh filename="package://mycobot_description/urdf/force_control_gripper/pro_gripper_left3.dae"/>
      </geometry>
    <origin xyz = "0 -0.03 0.012 " rpy = " 1.5708 3.14159 1.5708"/>
    </collision>
  </link>

  <link name="gripper_right1">
    <visual>
      <geometry>
       <mesh filename="package://mycobot_description/urdf/force_control_gripper/pro_gripper_right1.dae"/>
      </geometry>
    <origin xyz = "0.047 -0.013 -0.046 " rpy = " 1.5708 3.14 -1.5708"/>
    </visual>
    <collision>
      <geometry>
       <mesh filename="package://mycobot_description/urdf/force_control_gripper/pro_gripper_right1.dae"/>
      </geometry>
        <origin xyz = "0.047 -0.013 -0.046 " rpy = " 1.5708 3.14 -1.5708"/>
    </collision>
  </link>

  <link name="gripper_right2">
    <visual>
      <geometry>
       <mesh filename="package://mycobot_description/urdf/force_control_gripper/pro_gripper_right2.dae"/>
      </geometry>
    <origin xyz = "0 0.03 -0.005 " rpy = " 0 0 1.5708"/>
    </visual>
    <collision>
      <geometry>
       <mesh filename="package://mycobot_description/urdf/force_control_gripper/pro_gripper_right2.dae"/>
      </geometry>
        <origin xyz = "0 0.03 -0.005 " rpy = " 0 0 1.5708"/>
    </collision>
  </link>

  <link name="gripper_right3">
    <visual>
      <geometry>
       <mesh filename="package://mycobot_description/urdf/force_control_gripper/pro_gripper_right3.dae"/>
      </geometry>
    <origin xyz = "-0.014 -0.029 0.004 " rpy = " 3.14 0 -1.5708"/>

    </visual>
    <collision>
      <geometry>
       <mesh filename="package://mycobot_description/urdf/force_control_gripper/pro_gripper_right3.dae"/>
      </geometry>
    <origin xyz = "-0.014 -0.029 0.004 " rpy = " 3.14 0 -1.5708"/>
    </collision>
  </link>


  <joint name="gripper_controller" type="revolute">
    <axis xyz="0 0 1"/>
    <limit effort = "1000.0" lower = "0" upper = "1" velocity = "0"/>
    <parent link="gripper_base"/>
    <child link="gripper_left3"/>
    <origin xyz= "-0.018 0.016 -0.02" rpy = "0 0 0"/> 
  </joint>

  <joint name="gripper_base_to_gripper_left2" type="revolute">
    <axis xyz="0 0 1"/>
    <limit effort = "1000.0" lower = "-0.8" upper = "0.5" velocity = "0"/>
    <parent link="gripper_base"/>
    <child link="gripper_left2"/>
    <origin xyz= "-0.0445 -0.004 -0.02" rpy = "0 0 0"/> 
    <mimic joint="gripper_controller" multiplier="1.0" offset="0" />
  </joint>

  <joint name="gripper_left3_to_gripper_left1" type="revolute">
    <axis xyz="0 0 1"/>
    <limit effort = "1000.0" lower = "-0.5" upper = "0.5" velocity = "0"/>
    <parent link="gripper_left3"/>
    <child link="gripper_left1"/>
    <origin xyz= "0.01 0.06 0.0" rpy = "0 0 0"/> 
    <mimic joint="gripper_controller" multiplier="-1.0" offset="0" />
  </joint>

  <joint name="gripper_base_to_gripper_right3" type="revolute">
    <axis xyz="0 0 1"/>
    <limit effort = "1000.0" lower = "1" upper = "0" velocity = "0"/>
    <parent link="gripper_base"/>
    <child link="gripper_right3"/>
    <origin xyz= "0.018 0.015 -0.0212" rpy = "0 0 0"/> 
    <mimic joint="gripper_controller" multiplier="-1.0" offset="0" />
  </joint>

  <joint name="gripper_base_to_gripper_right2" type="revolute">
    <axis xyz="0 0 1"/>
    <limit effort = "1000.0" lower = "-0.5" upper = "0.8" velocity = "0"/>
    <parent link="gripper_base"/>
    <child link="gripper_right2"/>
    <origin xyz= "0.0442 -0.004 -0.02" rpy = "0 0 0"/> 
    <mimic joint="gripper_controller" multiplier="-1.0" offset="0" />
  </joint>

  <joint name="gripper_right3_to_gripper_right1" type="revolute">
    <axis xyz="0 0 1"/>
    <limit effort = "1000.0" lower = "-0.5" upper = "0.5" velocity = "0"/>
    <parent link="gripper_right3"/>
    <child link="gripper_right1"/>
    <origin xyz= "-0.01 0.061 0.001" rpy = "0 0 0"/> 
    <mimic joint="gripper_controller" multiplier="1.0" offset="0" />
  </joint>


</robot>

