<?xml version="1.0"?>
<robot xmlns:xacro="http://www.ros.org/wiki/xacro" name="firefighter">

  <xacro:property name="width" value=".2" />


  <link name="base">
    <visual>
      <geometry>
        <mesh filename="package://mycobot_description/urdf/new_320_urdf/base.dae"/>
      </geometry>
      <origin xyz = "0 0 0 " rpy = " 0 0 1.5708"/>
    </visual>
    <collision>
      <origin xyz = "0 0 0 " rpy = " 0 0 1.5708"/>
      <geometry>
        <cylinder length="0.102" radius="0.0725"/>
      </geometry>
    </collision>
  </link>

  <link name="link1">
    <visual>
      <geometry>
        <mesh filename="package://mycobot_description/urdf/new_320_urdf/link1.dae"/>
      </geometry>
     <origin xyz = "0.0 0.0 -0.078 " rpy = " 0 0 1.5708"/>
    </visual>
    <collision>
      <origin xyz = "0.0 0.0 -0.078 " rpy = " 0 0 1.5708"/>
      <geometry>
        <cylinder length="0.106" radius="0.043"/>
      </geometry>
    </collision>
  </link>


  <link name="link2">
    <visual>
      <geometry>
        <mesh filename="package://mycobot_description/urdf/new_320_urdf/link2.dae"/>
      </geometry>
      <origin xyz = "0.0 0.0 -0.04 " rpy = " 0 1.5708 0"/>
    </visual>
    <collision>
      <origin xyz = "0.0 0.0 -0.04 " rpy = " 0 1.5708 0"/>
      <geometry>
        <cylinder length="0.18" radius="0.036"/>
      </geometry>
    </collision>
  </link>


  <link name="link3">
    <visual>
      <geometry>
        <mesh filename="package://mycobot_description/urdf/new_320_urdf/link3.dae"/>
      </geometry>
       <origin xyz = "0.0 0.0 0.039 " rpy = " 1.5708 1.5708 1.5708"/>
    </visual>
    <collision>
      <origin xyz = "0.0 0.0 0.039 " rpy = " 1.5708 1.5708 1.5708"/>
      <geometry>
        <cylinder length="0.14" radius="0.0305"/>
      </geometry>
    </collision>
  </link>



  <link name="link4">
    <visual>
      <geometry>
        <mesh filename="package://mycobot_description/urdf/new_320_urdf/link4.dae"/>
      </geometry>
       <origin xyz = "0.0 -0.0024 -0.05" rpy = " 1.5708 1.5708 0"/>
    </visual>
    <collision>
      <origin xyz = "0.0 -0.0024 -0.05" rpy = " 1.5708 1.5708 0"/>
      <geometry>
        <cylinder length="0.083" radius="0.029"/>
      </geometry>
    </collision>
  </link>


  <link name="link5">
    <visual>
      <geometry>
        <mesh filename="package://mycobot_description/urdf/new_320_urdf/link5.dae"/>
      </geometry>
      <origin xyz = "0.0 0.0 -0.05 " rpy = " 0  0 -1.5708"/>
    </visual>
    <collision>
      <origin xyz = "0.0 0.0 -0.05 " rpy = " 0  0 -1.5708"/>
      <geometry>
        <cylinder length="0.0849" radius="0.029"/>
      </geometry>
    </collision>
  </link>

  <link name="link6">
    <visual>
      <geometry>
        <mesh filename="package://mycobot_description/urdf/new_320_urdf/link6.dae"/>
      </geometry>
      <material name = "grey">
        <color rgba = "0.5 0.5 0.5 1"/>
      </material>
      <origin xyz = "0.0 0.0 -0.0115 " rpy = " 1.5708 1.5708 0"/>
    </visual>
    <collision>
      <origin xyz = "0.0 0.0 -0.0115 " rpy = " 1.5708 1.5708 0"/>
      <geometry>
        <cylinder length="0.0225" radius="0.026"/>
      </geometry>
    </collision>
  </link>

  <joint name="joint2_to_joint1" type="revolute">
    <axis xyz="0 0 1"/>
    <limit effort = "1000.0" lower = "-2.96" upper = "2.96" velocity = "0"/>
    <parent link="base"/>
    <child link="link1"/>
    <origin xyz= "0 0 0.173" rpy = "0 0 0"/>
  </joint>


  <joint name="joint3_to_joint2" type="revolute">
    <axis xyz="0 0 1"/>
    <limit effort = "1000.0" lower = "-2.79" upper = "2.79" velocity = "0"/>
    <parent link="link1"/>
    <child link="link2"/>
    <origin xyz= "0 -0.086 0" rpy = "0 -1.57080  1.57080"/>
  </joint>


  <joint name="joint4_to_joint3" type="revolute">
    <axis xyz=" 0 0 1"/>
    <limit effort = "1000.0" lower = "-2.79" upper = "2.79" velocity = "0"/>
    <parent link="link2"/>
    <child link="link3"/>
    <origin xyz= "0.13635 0 -0.086   " rpy = "0 0 0"/>
  </joint>

  <joint name="joint5_to_joint4" type="revolute">
    <axis xyz=" 0 0 1"/>
    <limit effort = "1000.0" lower = "-2.79" upper = "2.79" velocity = "0"/>
    <parent link="link3"/>
    <child link="link4"/>
    <origin xyz= "0.1195 0  0.082" rpy = "0 0 1.57080"/>
  </joint>

  <joint name="joint6_to_joint5" type="revolute">
    <axis xyz="0 0 1"/>
    <limit effort = "1000.0" lower = "-2.96" upper = "2.96" velocity = "0"/>
    <parent link="link4"/>
    <child link="link5"/>
    <origin xyz= "0 -0.09415 0" rpy = "1.57080 0 0"/>
  </joint>

  <joint name="joint6output_to_joint6" type="revolute">
    <axis xyz="0 0 1"/>
    <limit effort = "1000.0" lower = "-3.05" upper = "3.05" velocity = "0"/>
    <parent link="link5"/>
    <child link="link6"/>
    <origin xyz= "0 0.055 0" rpy = "-1.57080 0 0 "/>
  </joint>

</robot>

